<?xml version="1.0"?>
<robot name="mycobot" xmlns:xacro="http://www.ros.org/wiki/xacro">

  <material name="red">
    <color rgba="1.0 0.0 0.0 1.0" />
  </material>
  <material name="green">
    <color rgba="0.0 1.0 0.0 1.0" />
  </material>
  <material name="blue">
    <color rgba="0.0 0.0 1.0 1.0" />
  </material>
  <material name="white">
    <color rgba="1.0 1.0 1.0 1.0" />
  </material>

  <link name="base_link" />

  <joint name="base_joint" type="fixed">
    <parent link="base_link"/>
    <child link="link1"/>
    <origin xyz="0 0 0" rpy="0 0 1.57" />
  </joint> 

  <link name="link1">
    <visual>
      <geometry>
        <mesh filename="package://mycobot_description/meshes/dae/link1.dae" />
      </geometry>
      <origin xyz="0 0 0" rpy="0 0 0" />
    </visual>
  </link>

  <link name="link2">
    <visual>
      <geometry>
        <mesh filename="package://mycobot_description/meshes/dae/link2.dae" />
      </geometry>
      <origin xyz="0 0 0" rpy="0 0 0" />
    </visual>
  </link>

  <link name="link3">
    <visual>
      <geometry>
        <mesh filename="package://mycobot_description/meshes/dae/link3.dae" />
      </geometry>
      <origin xyz="0 0 0" rpy="0 0 0" />
    </visual>
  </link>

  <link name="link4">
    <visual>
      <geometry>
        <mesh filename="package://mycobot_description/meshes/dae/link4.dae" />
      </geometry>
      <origin xyz="0 0 0" rpy="0 0 0" />
    </visual>
  </link>

  <link name="link5">
    <visual>
      <geometry>
        <mesh filename="package://mycobot_description/meshes/dae/link5.dae" />
      </geometry>
      <origin xyz="0 0 0" rpy="0 0 0" />
    </visual>
  </link>

  <link name="link6">
    <visual>
      <geometry>
        <mesh filename="package://mycobot_description/meshes/dae/link6.dae" />
      </geometry>
      <origin xyz="0 0 0" rpy="0 0 0" />
    </visual>
  </link>

  <link name="link6_flange">
    <visual>
      <geometry>
        <cylinder length="0.005" radius="0.02"/>
      </geometry>
        <origin xyz="0 0.0025 0" rpy="1.57 0 0" />
      <material name="white" />
    </visual>
  </link>

  <joint name="joint1" type="revolute">
    <axis xyz="0 0 1" />
    <limit effort="1000.0" lower="-3.14" upper="3.14159" velocity="0" />
    <parent link="link1" />
    <child link="link2" />
    <origin xyz="0 0 0.0706" rpy="0 0 0" />    
  </joint>

  <joint name="joint2" type="revolute">
    <axis xyz="1 0 0" />
    <limit effort="1000.0" lower="-3.14" upper="3.14159" velocity="0" />
    <parent link="link2" />
    <child link="link3" />
    <origin xyz="0.03256 0 0.05976" rpy="0 0 0" />    
  </joint>

  <joint name="joint3" type="revolute">
    <axis xyz="1 0 0" />
    <limit effort = "1000.0" lower = "-3.14" upper = "3.14159" velocity = "0" />
    <parent link="link3" />
    <child link="link4" />
    <origin xyz=" 0.00272 0 0.1104" rpy="0 0 0" />    
  </joint>

  <joint name="joint4" type="revolute">
    <axis xyz="1 0 0" />
    <limit effort="1000.0" lower="-3.14" upper="3.14159" velocity="0" />
    <parent link="link4" />
    <child link="link5" />
    <origin xyz="-0.00164 0 0.096" rpy="0 0 0" />    
  </joint>

  <joint name="joint5" type="revolute">
    <axis xyz="0 0 1" />
    <limit effort="1000.0" lower="-3.14" upper="3.14159" velocity="0" />
    <parent link="link5" />
    <child link="link6" />
    <origin xyz="0.0298 0 0.02876" rpy="0 0 0" />
  </joint>

  <joint name="joint6" type="revolute">
    <axis xyz="0 1 0" />
    <limit effort="1000.0" lower="-3.14" upper="3.14159" velocity="0" />
    <parent link="link6" />
    <child link="link6_flange" />
    <origin xyz= "0 0.0456 0.03792" rpy="0 0 0" />    
  </joint>
</robot>
